Workbook

Sheet FrontSheet
B1: WORKBOOK OVERVIEW
B2: This workbook evaluates the risk–return profile of a two-asset portfolio using historical weekly return data. Under sheet "WEEKLY_RETURNS", return distributions are analysed to estimate volatility, correlation, and Value at Risk (VaR). Under sheet "Risk_and_Portfolio_Metrics", portfolio optimisation techniques are then applied to construct the efficient frontier, identify minimum-variance and maximum risk-adjusted portfolios, and assess diversification effects. The impact of introducing a risk-free asset is examined, and sensitivity analysis is performed to evaluate changes in portfolio performance under varying assumptions. Key results are summarised on this sheet, with supporting calculations provided in subsequent worksheets.
B7: ASSET 1 STOCK TICKER: AMZN
B8: ASSET 2 STOCK TICKER: TSLA
B9: Below are histograms based on 150 weeks worth of weekly return data, as plotted in WEEKLY_RETURNS sheet
A12: =CONCATENATE("Histogram1: Returns of ",B4) -> Histogram1: Returns of | C12: =CONCATENATE("Histogram2: Returns of ",B5) -> Histogram2: Returns of
B36: Below are Mean and SD and VaR as calculated in WEEKLY_Returns sheet
B39: Mean | C39: StdDev | D39: Corelation
A40: =B3 -> 0 | B40: 0.00557303 | C40: 0.086264374 | D40: 0.44047306
A41: =B4 -> 0 | B41: 0.00484608 | C41: 0.046127251
B43: VaR of the loss on the rate of returns at confidence level 95%, viewing the histograms as Probability mass functions
B45: VaR
A46: =B3 -> 0 | B46: -0.37868143
A47: =B4 -> 0 | B47: -0.099178818
B49: Below is the efficient frontier in the μ-σ plane, plotted after computing the expected returns,the standard deviations, and the Sharpe ratios (Check Sheet : Risk_and_Portfolio_Metrics)
B72: Suppose a money market account with weekly interest rate 0.1% is added, what is the market portfolio and its Sharpe ratio?
A73: Interest rate | B73: 0.001
A74: Market portfolio | B74: (90%, 10%)
A75: omega1 | B75: 0.9
A76: Expected return | B76: 0.004918776
A77: Std.Dev | B77: 0.045971272
A78: Sharpe ratio | B78: 0.10699672
B81: How does the sharpe ratio change if the weekly interest rate decreases? Let us decrease our interest rate tenfold and observe | C81: Sharpe ratio increases as interest rate decreases
A82: Interest rate | B82: 0.001 | C82: =B82-0.0005 -> 0.0005 | D82: 0
A83: Sharpe ratio | B83: 0.085233129 | C83: 0.096117647 | D83: 0.10699672

Sheet WEEKLY_RETURNS
A1: {=_xlfn.STOCKHISTORY("AMZN", TODAY()-(7*150), TODAY(),1,1)} -> Date | B1: Close | C1: Amazon Returns | E1: {=_xlfn.STOCKHISTORY("TSLA", TODAY()-(7*150), TODAY(),1,1)} -> Date | F1: Close | G1: Tesla Returns | H1: Bank rate | I1: AMZN | M1: TSLA
A2: 45264 | B2: 147.42 | E2: 45264 | F2: 243.84 | H2: =Risk_and_Portfolio_Metrics!$O$49 -> 0.001 | I2: Average | J2: =AVERAGE(C3:C152) -> -0.0022276395 | M2: Average | N2: =AVERAGE(G3:G152) -> -0.0015486404
A3: 45271 | B3: 149.97 | C3: =(B3-B2)/B2 -> 0.017297517 | E3: 45271 | F3: 253.5 | G3: =(F3-F2)/F2 -> 0.039616142 | H3: =Risk_and_Portfolio_Metrics!$O$49 -> 0.001 | I3: Std. Dev | J3: =STDEV(C3:C152) -> 0.092642332 | M3: Std. Dev | N3: =STDEV(G3:G152) -> 0.11033813
A4: 45278 | B4: 153.42 | C4: =(B4-B3)/B3 -> 0.023004601 | E4: 45278 | F4: 252.54 | G4: =(F4-F3)/F3 -> -0.0037869822 | H4: =Risk_and_Portfolio_Metrics!$O$49 -> 0.001
A5: 45286 | B5: 151.94 | C5: =(B5-B4)/B4 -> -0.0096467214 | E5: 45286 | F5: 248.48 | G5: =(F5-F4)/F4 -> -0.016076661 | H5: =Risk_and_Portfolio_Metrics!$O$49 -> 0.001 | I5: Confidence level | J5: 0.95 | M5: Confidence Level | N5: 0.95
A6: 45293 | B6: 145.24 | C6: =(B6-B5)/B5 -> -0.044096354 | E6: 45293 | F6: 237.49 | G6: =(F6-F5)/F5 -> -0.044228912 | H6: =Risk_and_Portfolio_Metrics!$O$49 -> 0.001 | I6: lower bound | J6: {=INDEX(I18:I28, MATCH(TRUE, K19:K29 > (1 - $J$5), 0))} -> -0.064 | K6: {=INDEX(K18:K28, MATCH(TRUE, K18:K28 > (1 - J5), 0))} -> 0.83892617 | M6: Lower Bound | N6: {=INDEX(M18:M28, MATCH(TRUE, O19:O29 > (1 - $N$5), 0))} -> -0.226 | O6: {=INDEX(O18:O28, MATCH(TRUE, O18:O28 > (1 - N5), 0))} -> 0.067114094
A7: 45299 | B7: 154.62 | C7: =(B7-B6)/B6 -> 0.06458276 | E7: 45299 | F7: 218.89 | G7: =(F7-F6)/F6 -> -0.078319087 | H7: =Risk_and_Portfolio_Metrics!$O$49 -> 0.001 | I7: Upper Bound | J7: {=INDEX(I18:I28, MATCH(TRUE, K18:K29 > (1 - J5), 0))} -> 0.053 | K7: {=INDEX(K18:K28, MATCH(TRUE, K19:K28 > (1 - J5), 0))} -> 0.040268456 | M7: Upper Bound | N7: {=INDEX(M18:M28, MATCH(TRUE, O18:O29 > (1 - N5), 0))} -> -0.097 | O7: {=INDEX(O18:O28, MATCH(TRUE, O19:O28 > (1 - N5), 0))} -> 0
A8: 45307 | B8: 155.34 | C8: =(B8-B7)/B7 -> 0.0046565774 | E8: 45307 | F8: 212.19 | G8: =(F8-F7)/F7 -> -0.030608982 | H8: =Risk_and_Portfolio_Metrics!$O$49 -> 0.001 | I8: VaR | J8: =J7+(((1-0.95)-J6)/(K6-K7))*(J6-J7) -> 0.036299479 | M8: VaR | N8: =N7+(((1-0.95)-N6)/(O6-O7))*(N6-N7) -> -0.6274996
A9: 45313 | B9: 159.12 | C9: =(B9-B8)/B8 -> 0.02433372 | E9: 45313 | F9: 183.25 | G9: =(F9-F8)/F8 -> -0.1363872 | H9: =Risk_and_Portfolio_Metrics!$O$49 -> 0.001
A10: 45320 | B10: 171.81 | C10: =(B10-B9)/B9 -> 0.079751131 | E10: 45320 | F10: 187.91 | G10: =(F10-F9)/F9 -> 0.025429741 | H10: =Risk_and_Portfolio_Metrics!$O$49 -> 0.001
A11: 45327 | B11: 174.45 | C11: =(B11-B10)/B10 -> 0.015365811 | E11: 45327 | F11: 193.57 | G11: =(F11-F10)/F10 -> 0.030120803 | H11: =Risk_and_Portfolio_Metrics!$O$49 -> 0.001 | I11: Correlation of Amazon and Tesla stock weekly rate or returns | O11: =CORREL(C3:C152,G3:G152) -> 0.76682223
A12: 45334 | B12: 169.51 | C12: =(B12-B11)/B11 -> -0.02831757 | E12: 45334 | F12: 199.95 | G12: =(F12-F11)/F11 -> 0.032959653 | H12: =Risk_and_Portfolio_Metrics!$O$49 -> 0.001
A13: 45342 | B13: 174.99 | C13: =(B13-B12)/B12 -> 0.032328476 | E13: 45342 | F13: 191.97 | G13: =(F13-F12)/F12 -> -0.039909977 | H13: =Risk_and_Portfolio_Metrics!$O$49 -> 0.001
A14: 45348 | B14: 178.22 | C14: =(B14-B13)/B13 -> 0.018458198 | E14: 45348 | F14: 202.64 | G14: =(F14-F13)/F13 -> 0.055581601 | H14: =Risk_and_Portfolio_Metrics!$O$49 -> 0.001
A15: 45355 | B15: 175.35 | C15: =(B15-B14)/B14 -> -0.016103692 | E15: 45355 | F15: 175.34 | G15: =(F15-F14)/F14 -> -0.13472167 | H15: =Risk_and_Portfolio_Metrics!$O$49 -> 0.001
A16: 45362 | B16: 174.42 | C16: =(B16-B15)/B15 -> -0.0053036784 | E16: 45362 | F16: 163.57 | G16: =(F16-F15)/F15 -> -0.067126725 | H16: =Risk_and_Portfolio_Metrics!$O$49 -> 0.001 | I16: Histogram table for AMZN | M16: Histogram table for TSLA
A17: 45369 | B17: 178.87 | C17: =(B17-B16)/B16 -> 0.025513129 | E17: 45369 | F17: 170.83 | G17: =(F17-F16)/F16 -> 0.044384667 | H17: =Risk_and_Portfolio_Metrics!$O$49 -> 0.001 | I17: Bin | J17: Frequency | K17: Probability | M17: Bin | N17: Frequency | O17: Probability
A18: 45376 | B18: 180.38 | C18: =(B18-B17)/B17 -> 0.0084418852 | E18: 45376 | F18: 175.79 | G18: =(F18-F17)/F17 -> 0.029034713 | H18: =Risk_and_Portfolio_Metrics!$O$49 -> 0.001 | I18: =ROUND((MIN($C$3:$C$152)),3) -> -1 | J18: {=FREQUENCY(C3:C152,I18:I28)} -> 1 | K18: =J18/SUM($J$18:$J$28) -> 0.0067114094 | M18: =ROUND((MIN($G$3:$G$152)),3) -> -1 | N18: {=FREQUENCY(G3:G152,M18:M28)} -> 1 | O18: =N18/SUM($N$18:$N$28) -> 0.0067114094
A19: 45383 | B19: 185.07 | C19: =(B19-B18)/B18 -> 0.026000665 | E19: 45383 | F19: 164.9 | G19: =(F19-F18)/F18 -> -0.061948916 | H19: =Risk_and_Portfolio_Metrics!$O$49 -> 0.001 | I19: =I18+ROUND((MAX($C$3:$C$152)-MIN($C$3:$C$152))/10,3) -> -0.883 | J19: 0 | K19: =J19/SUM($J$18:$J$28) -> 0 | M19: =M18+ROUND((MAX($G$3:$G$152)-MIN($G$3:$G$152))/10,3) -> -0.871 | N19: 0 | O19: =N19/SUM($N$18:$N$28) -> 0
A20: 45390 | B20: 186.13 | C20: =(B20-B19)/B19 -> 0.0057275625 | E20: 45390 | F20: 171.05 | G20: =(F20-F19)/F19 -> 0.037295331 | H20: =Risk_and_Portfolio_Metrics!$O$49 -> 0.001 | I20: =I19+ROUND((MAX($C$3:$C$152)-MIN($C$3:$C$152))/10,3) -> -0.766 | J20: 0 | K20: =J20/SUM($J$18:$J$28) -> 0 | M20: =M19+ROUND((MAX($G$3:$G$152)-MIN($G$3:$G$152))/10,3) -> -0.742 | N20: 0 | O20: =N20/SUM($N$18:$N$28) -> 0
A21: 45397 | B21: 174.63 | C21: =(B21-B20)/B20 -> -0.061784774 | E21: 45397 | F21: 147.05 | G21: =(F21-F20)/F20 -> -0.14030985 | H21: =Risk_and_Portfolio_Metrics!$O$49 -> 0.001 | I21: =I20+ROUND((MAX($C$3:$C$152)-MIN($C$3:$C$152))/10,3) -> -0.649 | J21: 0 | K21: =J21/SUM($J$18:$J$28) -> 0 | M21: =M20+ROUND((MAX($G$3:$G$152)-MIN($G$3:$G$152))/10,3) -> -0.613 | N21: 0 | O21: =N21/SUM($N$18:$N$28) -> 0
A22: 45404 | B22: 179.62 | C22: =(B22-B21)/B21 -> 0.028574701 | E22: 45404 | F22: 168.29 | G22: =(F22-F21)/F21 -> 0.14444067 | H22: =Risk_and_Portfolio_Metrics!$O$49 -> 0.001 | I22: =I21+ROUND((MAX($C$3:$C$152)-MIN($C$3:$C$152))/10,3) -> -0.532 | J22: 0 | K22: =J22/SUM($J$18:$J$28) -> 0 | M22: =M21+ROUND((MAX($G$3:$G$152)-MIN($G$3:$G$152))/10,3) -> -0.484 | N22: 0 | O22: =N22/SUM($N$18:$N$28) -> 0
A23: 45411 | B23: 186.21 | C23: =(B23-B22)/B22 -> 0.036688565 | E23: 45411 | F23: 181.19 | G23: =(F23-F22)/F22 -> 0.076653396 | H23: =Risk_and_Portfolio_Metrics!$O$49 -> 0.001 | I23: =I22+ROUND((MAX($C$3:$C$152)-MIN($C$3:$C$152))/10,3) -> -0.415 | J23: 0 | K23: =J23/SUM($J$18:$J$28) -> 0 | M23: =M22+ROUND((MAX($G$3:$G$152)-MIN($G$3:$G$152))/10,3) -> -0.355 | N23: 0 | O23: =N23/SUM($N$18:$N$28) -> 0
A24: 45418 | B24: 187.48 | C24: =(B24-B23)/B23 -> 0.0068202567 | E24: 45418 | F24: 168.47 | G24: =(F24-F23)/F23 -> -0.07020255 | H24: =Risk_and_Portfolio_Metrics!$O$49 -> 0.001 | I24: =I23+ROUND((MAX($C$3:$C$152)-MIN($C$3:$C$152))/10,3) -> -0.298 | J24: 0 | K24: =J24/SUM($J$18:$J$28) -> 0 | M24: =M23+ROUND((MAX($G$3:$G$152)-MIN($G$3:$G$152))/10,3) -> -0.226 | N24: 0 | O24: =N24/SUM($N$18:$N$28) -> 0
A25: 45425 | B25: 184.7 | C25: =(B25-B24)/B24 -> -0.014828248 | E25: 45425 | F25: 177.46 | G25: =(F25-F24)/F24 -> 0.053362616 | H25: =Risk_and_Portfolio_Metrics!$O$49 -> 0.001 | I25: =I24+ROUND((MAX($C$3:$C$152)-MIN($C$3:$C$152))/10,3) -> -0.181 | J25: 0 | K25: =J25/SUM($J$18:$J$28) -> 0 | M25: =M24+ROUND((MAX($G$3:$G$152)-MIN($G$3:$G$152))/10,3) -> -0.097 | N25: 10 | O25: =N25/SUM($N$18:$N$28) -> 0.067114094
A26: 45432 | B26: 180.75 | C26: =(B26-B25)/B25 -> -0.021386031 | E26: 45432 | F26: 179.24 | G26: =(F26-F25)/F25 -> 0.010030429 | H26: =Risk_and_Portfolio_Metrics!$O$49 -> 0.001 | I26: =I25+ROUND((MAX($C$3:$C$152)-MIN($C$3:$C$152))/10,3) -> -0.064 | J26: 6 | K26: =J26/SUM($J$18:$J$28) -> 0.040268456 | M26: =M25+ROUND((MAX($G$3:$G$152)-MIN($G$3:$G$152))/10,3) -> 0.032 | N26: 91 | O26: =N26/SUM($N$18:$N$28) -> 0.61073826
A27: 45440 | B27: 176.44 | C27: =(B27-B26)/B26 -> -0.02384509 | E27: 45440 | F27: 178.08 | G27: =(F27-F26)/F26 -> -0.0064717697 | H27: =Risk_and_Portfolio_Metrics!$O$49 -> 0.001 | I27: =I26+ROUND((MAX($C$3:$C$152)-MIN($C$3:$C$152))/10,3) -> 0.053 | J27: 125 | K27: =J27/SUM($J$18:$J$28) -> 0.83892617 | M27: =M26+ROUND((MAX($G$3:$G$152)-MIN($G$3:$G$152))/10,3) -> 0.161 | N27: 43 | O27: =N27/SUM($N$18:$N$28) -> 0.2885906
A28: 45446 | B28: 184.3 | C28: =(B28-B27)/B27 -> 0.044547722 | E28: 45446 | F28: 177.48 | G28: =(F28-F27)/F27 -> -0.0033692722 | H28: =Risk_and_Portfolio_Metrics!$O$49 -> 0.001 | I28: =I27+ROUND((MAX($C$3:$C$152)-MIN($C$3:$C$152))/10,3) -> 0.17 | J28: 17 | K28: =J28/SUM($J$18:$J$28) -> 0.11409396 | M28: =M27+ROUND((MAX($G$3:$G$152)-MIN($G$3:$G$152))/10,3) -> 0.29 | N28: 4 | O28: =N28/SUM($N$18:$N$28) -> 0.026845638
A29: 45453 | B29: 183.66 | C29: =(B29-B28)/B28 -> -0.003472599 | E29: 45453 | F29: 178.01 | G29: =(F29-F28)/F28 -> 0.002986252 | H29: =Risk_and_Portfolio_Metrics!$O$49 -> 0.001 | J29: 1 | K29: =J29/SUM($J$18:$J$28) -> 0.0067114094 | N29: 1
A30: 45460 | B30: 189.08 | C30: =(B30-B29)/B29 -> 0.029511053 | E30: 45460 | F30: 183.01 | G30: =(F30-F29)/F29 -> 0.02808831 | H30: =Risk_and_Portfolio_Metrics!$O$49 -> 0.001
A31: 45467 | B31: 193.25 | C31: =(B31-B30)/B30 -> 0.022054157 | E31: 45467 | F31: 197.88 | G31: =(F31-F30)/F30 -> 0.081252391 | H31: =Risk_and_Portfolio_Metrics!$O$49 -> 0.001
A32: 45474 | B32: 200 | C32: =(B32-B31)/B31 -> 0.034928849 | E32: 45474 | F32: 251.52 | G32: =(F32-F31)/F31 -> 0.27107338 | H32: =Risk_and_Portfolio_Metrics!$O$49 -> 0.001
A33: 45481 | B33: 194.49 | C33: =(B33-B32)/B32 -> -0.02755 | E33: 45481 | F33: 248.23 | G33: =(F33-F32)/F32 -> -0.013080471 | H33: =Risk_and_Portfolio_Metrics!$O$49 -> 0.001
A34: 45488 | B34: 183.13 | C34: =(B34-B33)/B33 -> -0.058409173 | E34: 45488 | F34: 239.2 | G34: =(F34-F33)/F33 -> -0.036377553 | H34: =Risk_and_Portfolio_Metrics!$O$49 -> 0.001
A35: 45495 | B35: 182.5 | C35: =(B35-B34)/B34 -> -0.0034401791 | E35: 45495 | F35: 219.8 | G35: =(F35-F34)/F34 -> -0.081103679 | H35: =Risk_and_Portfolio_Metrics!$O$49 -> 0.001
A36: 45502 | B36: 167.9 | C36: =(B36-B35)/B35 -> -0.08 | E36: 45502 | F36: 207.67 | G36: =(F36-F35)/F35 -> -0.055186533 | H36: =Risk_and_Portfolio_Metrics!$O$49 -> 0.001
A37: 45509 | B37: 166.94 | C37: =(B37-B36)/B36 -> -0.0057176891 | E37: 45509 | F37: 200 | G37: =(F37-F36)/F36 -> -0.036933597 | H37: =Risk_and_Portfolio_Metrics!$O$49 -> 0.001
A38: 45516 | B38: 177.06 | C38: =(B38-B37)/B37 -> 0.060620582 | E38: 45516 | F38: 216.12 | G38: =(F38-F37)/F37 -> 0.0806 | H38: =Risk_and_Portfolio_Metrics!$O$49 -> 0.001
A39: 45523 | B39: 177.04 | C39: =(B39-B38)/B38 -> -0.00011295606 | E39: 45523 | F39: 220.32 | G39: =(F39-F38)/F38 -> 0.019433648 | H39: =Risk_and_Portfolio_Metrics!$O$49 -> 0.001
A40: 45530 | B40: 178.5 | C40: =(B40-B39)/B39 -> 0.0082467239 | E40: 45530 | F40: 214.11 | G40: =(F40-F39)/F39 -> -0.028186275 | H40: =Risk_and_Portfolio_Metrics!$O$49 -> 0.001
...

Sheet Risk_and_Portfolio_Metrics
A1: omega1 | B1: omega2 | C1: Expected return | D1: StdDev | E1: Sharpe ratio(Risk Free Rate assumed to be 0) | F1: Sharpe Ratio(Risk Free return at weekly interest rate 0.1%) | G1: Sharpe Ratio(Risk Free return at weekly interest rate 0.05%) | H1: =WEEKLY_RETURNS!I1 -> AMZN | L1: =WEEKLY_RETURNS!M1 -> TSLA
A2: -0.95 | B2: =100%-A2 -> 1.95 | C2: =A2*$I$2 + B2*$M$2 -> -0.00090359119 | D2: =SQRT((A2^2)*($I$3^2) + (B2^2)*($M$3^2) + 2*A2*B2*$I$3*$M$3*$N$9) -> 0.1581073 | E2: =C2/D2 -> -0.0057150506 | F2: =(C2-$N$10)/D2 -> -0.012043033 | G2: =(C2-$N$11)/D2 -> -0.0088782508 | H2: =WEEKLY_RETURNS!I2 -> Average | I2: =WEEKLY_RETURNS!J2 -> -0.0022276395 | L2: =WEEKLY_RETURNS!M2 -> Average | M2: =WEEKLY_RETURNS!N2 -> -0.0015486404
A3: =A2+5% -> -0.9 | B3: =100%-A3 -> 1.9 | C3: =A3*$I$2 + B3*$M$2 -> -0.00093754115 | D3: =SQRT((A3^2)*($I$3^2) + (B3^2)*($M$3^2) + 2*A3*B3*$I$3*$M$3*$N$9) -> 0.15522368 | E3: =C3/D3 -> -0.0060399364 | F3: =(C3-$N$10)/D3 -> -0.012485475 | G3: =(C3-$N$11)/D3 -> -0.0092618999 | H3: =WEEKLY_RETURNS!I3 -> Std. Dev | I3: =WEEKLY_RETURNS!J3 -> 0.092642332 | L3: =WEEKLY_RETURNS!M3 -> Std. Dev | M3: =WEEKLY_RETURNS!N3 -> 0.11033813
A4: =A3+5% -> -0.85 | B4: =100%-A4 -> 1.85 | C4: =A4*$I$2 + B4*$M$2 -> -0.00097149111 | D4: =SQRT((A4^2)*($I$3^2) + (B4^2)*($M$3^2) + 2*A4*B4*$I$3*$M$3*$N$9) -> 0.15236885 | E4: =C4/D4 -> -0.006375917 | F4: =(C4-$N$10)/D4 -> -0.012942221 | G4: =(C4-$N$11)/D4 -> -0.0096582482
A5: =A4+5% -> -0.8 | B5: =100%-A5 -> 1.8 | C5: =A5*$I$2 + B5*$M$2 -> -0.0010054411 | D5: =SQRT((A5^2)*($I$3^2) + (B5^2)*($M$3^2) + 2*A5*B5*$I$3*$M$3*$N$9) -> 0.14954445 | E5: =C5/D5 -> -0.0067233595 | F5: =(C5-$N$10)/D5 -> -0.013413679 | G5: =(C5-$N$11)/D5 -> -0.010067683
A6: =A5+5% -> -0.75 | B6: =100%-A6 -> 1.75 | C6: =A6*$I$2 + B6*$M$2 -> -0.001039391 | D6: =SQRT((A6^2)*($I$3^2) + (B6^2)*($M$3^2) + 2*A6*B6*$I$3*$M$3*$N$9) -> 0.14675223 | E6: =C6/D6 -> -0.0070826249 | F6: =(C6-$N$10)/D6 -> -0.013900239 | G6: =(C6-$N$11)/D6 -> -0.01049058
A7: =A6+5% -> -0.7 | B7: =100%-A7 -> 1.7 | C7: =A7*$I$2 + B7*$M$2 -> -0.001073341 | D7: =SQRT((A7^2)*($I$3^2) + (B7^2)*($M$3^2) + 2*A7*B7*$I$3*$M$3*$N$9) -> 0.14399408 | E7: =C7/D7 -> -0.0074540631 | F7: =(C7-$N$10)/D7 -> -0.014402266 | G7: =(C7-$N$11)/D7 -> -0.010927296
A8: =A7+5% -> -0.65 | B8: =100%-A8 -> 1.65 | C8: =A8*$I$2 + B8*$M$2 -> -0.0011072909 | D8: =SQRT((A8^2)*($I$3^2) + (B8^2)*($M$3^2) + 2*A8*B8*$I$3*$M$3*$N$9) -> 0.14127199 | E8: =C8/D8 -> -0.0078380077 | F8: =(C8-$N$10)/D8 -> -0.014920092 | G8: =(C8-$N$11)/D8 -> -0.011378165 | H8: =WEEKLY_RETURNS!I8 -> VaR | L8: =WEEKLY_RETURNS!M8 -> VaR
A9: =A8+5% -> -0.6 | B9: =100%-A9 -> 1.6 | C9: =A9*$I$2 + B9*$M$2 -> -0.0011412409 | D9: =SQRT((A9^2)*($I$3^2) + (B9^2)*($M$3^2) + 2*A9*B9*$I$3*$M$3*$N$9) -> 0.13858808 | E9: =C9/D9 -> -0.0082347696 | F9: =(C9-$N$10)/D9 -> -0.015454007 | G9: =(C9-$N$11)/D9 -> -0.011843486 | H9: =WEEKLY_RETURNS!I11 -> Correlation of Amazon and Tesla stock weekly rate or returns | N9: =WEEKLY_RETURNS!O11 -> 0.76682223
A10: =A9+5% -> -0.55 | B10: =100%-A10 -> 1.55 | C10: =A10*$I$2 + B10*$M$2 -> -0.0011751909 | D10: =SQRT((A10^2)*($I$3^2) + (B10^2)*($M$3^2) + 2*A10*B10*$I$3*$M$3*$N$9) -> 0.13594461 | E10: =C10/D10 -> -0.0086446301 | F10: =(C10-$N$10)/D10 -> -0.016004246 | G10: =(C10-$N$11)/D10 -> -0.012323518 | H10: Risk free return at 0.1% | N10: =EXP(0.001)-1 -> 0.0010005002
A11: =A10+5% -> -0.5 | B11: =100%-A11 -> 1.5 | C11: =A11*$I$2 + B11*$M$2 -> -0.0012091408 | D11: =SQRT((A11^2)*($I$3^2) + (B11^2)*($M$3^2) + 2*A11*B11*$I$3*$M$3*$N$9) -> 0.13334399 | E11: =C11/D11 -> -0.0090678315 | F11: =(C11-$N$10)/D11 -> -0.016570983 | G11: =(C11-$N$11)/D11 -> -0.012818469 | H11: Risk free return at 0.05% | N11: =EXP(0.0005)-1 -> 0.00050012502
A12: =A11+5% -> -0.45 | B12: =100%-A12 -> 1.45 | C12: =A12*$I$2 + B12*$M$2 -> -0.0012430908 | D12: =SQRT((A12^2)*($I$3^2) + (B12^2)*($M$3^2) + 2*A12*B12*$I$3*$M$3*$N$9) -> 0.13078877 | E12: =C12/D12 -> -0.009504568 | F12: =(C12-$N$10)/D12 -> -0.017154309 | G12: =(C12-$N$11)/D12 -> -0.013328482
A13: =A12+5% -> -0.4 | B13: =100%-A13 -> 1.4 | C13: =A13*$I$2 + B13*$M$2 -> -0.0012770407 | D13: =SQRT((A13^2)*($I$3^2) + (B13^2)*($M$3^2) + 2*A13*B13*$I$3*$M$3*$N$9) -> 0.12828167 | E13: =C13/D13 -> -0.0099549742 | F13: =(C13-$N$10)/D13 -> -0.017754219 | G13: =(C13-$N$11)/D13 -> -0.013853622
A14: =A13+5% -> -0.35 | B14: =100%-A14 -> 1.35 | C14: =A14*$I$2 + B14*$M$2 -> -0.0013109907 | D14: =SQRT((A14^2)*($I$3^2) + (B14^2)*($M$3^2) + 2*A14*B14*$I$3*$M$3*$N$9) -> 0.12582557 | E14: =C14/D14 -> -0.010419112 | F14: =(C14-$N$10)/D14 -> -0.018370598 | G14: =(C14-$N$11)/D14 -> -0.014393861
A15: =A14+5% -> -0.3 | B15: =100%-A15 -> 1.3 | C15: =A15*$I$2 + B15*$M$2 -> -0.0013449406 | D15: =SQRT((A15^2)*($I$3^2) + (B15^2)*($M$3^2) + 2*A15*B15*$I$3*$M$3*$N$9) -> 0.1234235 | E15: =C15/D15 -> -0.010896958 | F15: =(C15-$N$10)/D15 -> -0.019003195 | G15: =(C15-$N$11)/D15 -> -0.014949063
A16: =A15+5% -> -0.25 | B16: =100%-A16 -> 1.25 | C16: =A16*$I$2 + B16*$M$2 -> -0.0013788906 | D16: =SQRT((A16^2)*($I$3^2) + (B16^2)*($M$3^2) + 2*A16*B16*$I$3*$M$3*$N$9) -> 0.12107868 | E16: =C16/D16 -> -0.011388384 | F16: =(C16-$N$10)/D16 -> -0.019651607 | G16: =(C16-$N$11)/D16 -> -0.015518963
A17: =A16+5% -> -0.2 | B17: =100%-A17 -> 1.2 | C17: =A17*$I$2 + B17*$M$2 -> -0.0014128406 | D17: =SQRT((A17^2)*($I$3^2) + (B17^2)*($M$3^2) + 2*A17*B17*$I$3*$M$3*$N$9) -> 0.11879451 | E17: =C17/D17 -> -0.011893146 | F17: =(C17-$N$10)/D17 -> -0.020315254 | G17: =(C17-$N$11)/D17 -> -0.016103147
A18: =A17+5% -> -0.15 | B18: =100%-A18 -> 1.15 | C18: =A18*$I$2 + B18*$M$2 -> -0.0014467905 | D18: =SQRT((A18^2)*($I$3^2) + (B18^2)*($M$3^2) + 2*A18*B18*$I$3*$M$3*$N$9) -> 0.11657455 | E18: =C18/D18 -> -0.01241086 | F18: =(C18-$N$10)/D18 -> -0.020993352 | G18: =(C18-$N$11)/D18 -> -0.016701033
A19: =A18+5% -> -0.1 | B19: =100%-A19 -> 1.1 | C19: =A19*$I$2 + B19*$M$2 -> -0.0014807405 | D19: =SQRT((A19^2)*($I$3^2) + (B19^2)*($M$3^2) + 2*A19*B19*$I$3*$M$3*$N$9) -> 0.11442254 | E19: =C19/D19 -> -0.012940986 | F19: =(C19-$N$10)/D19 -> -0.021684894 | G19: =(C19-$N$11)/D19 -> -0.017311847
A20: =A19+5% -> -0.05 | B20: =100%-A20 -> 1.05 | C20: =A20*$I$2 + B20*$M$2 -> -0.0015146904 | D20: =SQRT((A20^2)*($I$3^2) + (B20^2)*($M$3^2) + 2*A20*B20*$I$3*$M$3*$N$9) -> 0.11234238 | E20: =C20/D20 -> -0.013482805 | F20: =(C20-$N$10)/D20 -> -0.022388618 | G20: =(C20-$N$11)/D20 -> -0.017934598
A21: =A20+5% -> 3.1918912e-16 | B21: =100%-A21 -> 1 | C21: =A21*$I$2 + B21*$M$2 -> -0.0015486404 | D21: =SQRT((A21^2)*($I$3^2) + (B21^2)*($M$3^2) + 2*A21*B21*$I$3*$M$3*$N$9) -> 0.11033813 | E21: =C21/D21 -> -0.014035405 | F21: =(C21-$N$10)/D21 -> -0.023102988 | G21: =(C21-$N$11)/D21 -> -0.018568063
A22: =A21+5% -> 0.05 | B22: =100%-A22 -> 0.95 | C22: =A22*$I$2 + B22*$M$2 -> -0.0015825903 | D22: =SQRT((A22^2)*($I$3^2) + (B22^2)*($M$3^2) + 2*A22*B22*$I$3*$M$3*$N$9) -> 0.10841401 | E22: =C22/D22 -> -0.014597655 | F22: =(C22-$N$10)/D22 -> -0.023826168 | G22: =(C22-$N$11)/D22 -> -0.019210758
A23: =A22+5% -> 0.1 | B23: =100%-A23 -> 0.9 | C23: =A23*$I$2 + B23*$M$2 -> -0.0016165403 | D23: =SQRT((A23^2)*($I$3^2) + (B23^2)*($M$3^2) + 2*A23*B23*$I$3*$M$3*$N$9) -> 0.10657436 | E23: =C23/D23 -> -0.015168192 | F23: =(C23-$N$10)/D23 -> -0.024556005 | G23: =(C23-$N$11)/D23 -> -0.019860925
... A44: =A43+5% -> 1.15 | B44: =100%-A44 -> -0.15 | C44: =A44*$I$2 + B44*$M$2 -> -0.0023294894 | D44: =SQRT((A44^2)*($I$3^2) + (B44^2)*($M$3^2) + 2*A44*B44*$I$3*$M$3*$N$9) -> 0.094446568 | E44: =C44/D44 -> -0.024664627 | F44: =(C44-$N$10)/D44 -> -0.03525792 | G44: =(C44-$N$11)/D44 -> -0.02995995
A45: =A44+5% -> 1.2 | B45: =100%-A45 -> -0.2 | C45: =A45*$I$2 + B45*$M$2 -> -0.0023634394 | D45: =SQRT((A45^2)*($I$3^2) + (B45^2)*($M$3^2) + 2*A45*B45*$I$3*$M$3*$N$9) -> 0.095307261 | E45: =C45/D45 -> -0.024798104 | F45: =(C45-$N$10)/D45 -> -0.035295732 | G45: =(C45-$N$11)/D45 -> -0.030045606 | K45: Max Sharpe ratio | L45: Omega 1 | M45: Expected Return | N45: St Dev | O45: Ratio at R = 0.1% | P45: Ratio at R = 0.05%
A46: =A45+5% -> 1.25 | B46: =100%-A46 -> -0.25 | C46: =A46*$I$2 + B46*$M$2 -> -0.0023973893 | D46: =SQRT((A46^2)*($I$3^2) + (B46^2)*($M$3^2) + 2*A46*B46*$I$3*$M$3*$N$9) -> 0.096292236 | E46: =C46/D46 -> -0.024897016 | F46: =(C46-$N$10)/D46 -> -0.035287263 | G46: =(C46-$N$11)/D46 -> -0.030090841 | K46: =$E$39 -> -0.023446954 | L46: =$A$39 -> 0.9 | M46: =$C$39 -> -0.0021597396 | N46: =$D$39 -> 0.092111738 | O46: =$F$39 -> -0.034308763 | P46: =$G$39 -> -0.028876501
A47: =A46+5% -> 1.3 | B47: =100%-A47 -> -0.3 | C47: =A47*$I$2 + B47*$M$2 -> -0.0024313393 | D47: =SQRT((A47^2)*($I$3^2) + (B47^2)*($M$3^2) + 2*A47*B47*$I$3*$M$3*$N$9) -> 0.097397724 | E47: =C47/D47 -> -0.024962999 | F47: =(C47-$N$10)/D47 -> -0.035235315 | G47: =(C47-$N$11)/D47 -> -0.030097873 | K47: Portfolio Variance | L47: =SUM(K65:M65) -> 0.0074415422
A48: =A47+5% -> 1.35 | B48: =100%-A48 -> -0.35 | C48: =A48*$I$2 + B48*$M$2 -> -0.0024652893 | D48: =SQRT((A48^2)*($I$3^2) + (B48^2)*($M$3^2) + 2*A48*B48*$I$3*$M$3*$N$9) -> 0.098619672 | E48: =C48/D48 -> -0.024997946 | F48: =(C48-$N$10)/D48 -> -0.035142983 | G48: =(C48-$N$11)/D48 -> -0.030069196
A49: =A48+5% -> 1.4 | B49: =100%-A49 -> -0.4 | C49: =A49*$I$2 + B49*$M$2 -> -0.0024992392 | D49: =SQRT((A49^2)*($I$3^2) + (B49^2)*($M$3^2) + 2*A49*B49*$I$3*$M$3*$N$9) -> 0.099953808 | E49: =C49/D49 -> -0.025003942 | F49: =(C49-$N$10)/D49 -> -0.035013567 | G49: =(C49-$N$11)/D49 -> -0.030007503 | K49: Cov(A,A) | L49: =(FrontSheet!C40)^2 -> 0.0074415422 | N49: Interest RATE | O49: 0.001
A50: =A49+5% -> 1.45 | B50: =100%-A50 -> -0.45 | C50: =A50*$I$2 + B50*$M$2 -> -0.0025331892 | D50: =SQRT((A50^2)*($I$3^2) + (B50^2)*($M$3^2) + 2*A50*B50*$I$3*$M$3*$N$9) -> 0.1013957 | E50: =C50/D50 -> -0.0249832 | F50: =(C50-$N$10)/D50 -> -0.034850484 | G50: =(C50-$N$11)/D50 -> -0.029915608 | K50: Cov(B,B) | L50: =(FrontSheet!C41)^2 -> 0.0021277233
A51: =A50+5% -> 1.5 | B51: =100%-A51 -> -0.5 | C51: =A51*$I$2 + B51*$M$2 -> -0.0025671391 | D51: =SQRT((A51^2)*($I$3^2) + (B51^2)*($M$3^2) + 2*A51*B51*$I$3*$M$3*$N$9) -> 0.10294083 | E51: =C51/D51 -> -0.024938006 | F51: =(C51-$N$10)/D51 -> -0.034657183 | G51: =(C51-$N$11)/D51 -> -0.02979638 | K51: Cov(A,B) | L51: =(FrontSheet!C40)*(FrontSheet!C41)*FrontSheet!D40 -> 0.0017527033
A52: =A51+5% -> 1.55 | B52: =100%-A52 -> -0.55 | C52: =A52*$I$2 + B52*$M$2 -> -0.0026010891 | D52: =SQRT((A52^2)*($I$3^2) + (B52^2)*($M$3^2) + 2*A52*B52*$I$3*$M$3*$N$9) -> 0.10458462 | E52: =C52/D52 -> -0.024870666 | F52: =(C52-$N$10)/D52 -> -0.034437083 | G52: =(C52-$N$11)/D52 -> -0.029652679
A53: =A52+5% -> 1.6 | B53: =100%-A53 -> -0.6 | C53: =A53*$I$2 + B53*$M$2 -> -0.002635039 | D53: =SQRT((A53^2)*($I$3^2) + (B53^2)*($M$3^2) + 2*A53*B53*$I$3*$M$3*$N$9) -> 0.10632249 | E53: =C53/D53 -> -0.02478346 | F53: =(C53-$N$10)/D53 -> -0.034193512 | G53: =(C53-$N$11)/D53 -> -0.02948731 | K53: Covariance Matrix
A54: =A53+5% -> 1.65 | B54: =100%-A54 -> -0.65 | C54: =A54*$I$2 + B54*$M$2 -> -0.002668989 | D54: =SQRT((A54^2)*($I$3^2) + (B54^2)*($M$3^2) + 2*A54*B54*$I$3*$M$3*$N$9) -> 0.1081499 | E54: =C54/D54 -> -0.024678608 | F54: =(C54-$N$10)/D54 -> -0.033929659 | G54: =(C54-$N$11)/D54 -> -0.029302977 | K54: Stock A | L54: B | M54: Bank A/c
A55: =A54+5% -> 1.7 | B55: =100%-A55 -> -0.7 | C55: =A55*$I$2 + B55*$M$2 -> -0.002702939 | D55: =SQRT((A55^2)*($I$3^2) + (B55^2)*($M$3^2) + 2*A55*B55*$I$3*$M$3*$N$9) -> 0.1100624 | E55: =C55/D55 -> -0.024558242 | F55: =(C55-$N$10)/D55 -> -0.033648541 | G55: =(C55-$N$11)/D55 -> -0.029102255 | J55: Stock A | K55: =L49 -> 0.0074415422 | L55: =L51 -> 0.0017527033 | M55: =K57 -> 1.2925704e-36
A56: =A55+5% -> 1.75 | B56: =100%-A56 -> -0.75 | C56: =A56*$I$2 + B56*$M$2 -> -0.0027368889 | D56: =SQRT((A56^2)*($I$3^2) + (B56^2)*($M$3^2) + 2*A56*B56*$I$3*$M$3*$N$9) -> 0.11205562 | E56: =C56/D56 -> -0.024424378 | F56: =(C56-$N$10)/D56 -> -0.033352981 | G56: =(C56-$N$11)/D56 -> -0.028887563 | J56: B | K56: =L51 -> 0.0017527033 | L56: =L50 -> 0.0021277233 | M56: =L57 -> 1.9388556e-36
A57: =A56+5% -> 1.8 | B57: =100%-A57 -> -0.8 | C57: =A57*$I$2 + B57*$M$2 -> -0.0027708389 | D57: =SQRT((A57^2)*($I$3^2) + (B57^2)*($M$3^2) + 2*A57*B57*$I$3*$M$3*$N$9) -> 0.11412535 | E57: =C57/D57 -> -0.024278908 | F57: =(C57-$N$10)/D57 -> -0.033045585 | G57: =(C57-$N$11)/D57 -> -0.028661151 | J57: Bank a/c | K57: =_xlfn.COVARIANCE.S(WEEKLY_RETURNS!C3:C152,WEEKLY_RETURNS!H3:H152) -> 1.2925704e-36 | L57: =_xlfn.COVARIANCE.S(WEEKLY_RETURNS!G3:G152, WEEKLY_RETURNS!H3:H152) -> 1.9388556e-36 | M57: =_xlfn.COVARIANCE.S(WEEKLY_RETURNS!H3:H152, WEEKLY_RETURNS!H3:H152) -> 4.2601809e-37
A58: =A57+5% -> 1.85 | B58: =100%-A58 -> -0.85 | C58: =A58*$I$2 + B58*$M$2 -> -0.0028047888 | D58: =SQRT((A58^2)*($I$3^2) + (B58^2)*($M$3^2) + 2*A58*B58*$I$3*$M$3*$N$9) -> 0.11626749 | E58: =C58/D58 -> -0.024123586 | F58: =(C58-$N$10)/D58 -> -0.032728744 | G58: =(C58-$N$11)/D58 -> -0.028425089
A59: =A58+5% -> 1.9 | B59: =100%-A59 -> -0.9 | C59: =A59*$I$2 + B59*$M$2 -> -0.0028387388 | D59: =SQRT((A59^2)*($I$3^2) + (B59^2)*($M$3^2) + 2*A59*B59*$I$3*$M$3*$N$9) -> 0.11847812 | E59: =C59/D59 -> -0.023960026 | F59: =(C59-$N$10)/D59 -> -0.032404624 | G59: =(C59-$N$11)/D59 -> -0.028181269 | K59: Stock A | L59: Stock B | M59: Bank A/c
A60: =A59+5% -> 1.95 | B60: =100%-A60 -> -0.95 | C60: =A60*$I$2 + B60*$M$2 -> -0.0028726887 | D60: =SQRT((A60^2)*($I$3^2) + (B60^2)*($M$3^2) + 2*A60*B60*$I$3*$M$3*$N$9) -> 0.12075347 | E60: =C60/D60 -> -0.023789699 | F60: =(C60-$N$10)/D60 -> -0.032075176 | G60: =(C60-$N$11)/D60 -> -0.027931402 | J60: Expected Return | K60: =AVERAGE(WEEKLY_RETURNS!C3:C152) -> -0.0022276395 | L60: =AVERAGE(WEEKLY_RETURNS!G3:G152) -> -0.0015486404 | M60: =O49 -> 0.001
...
